<?xml version="1.0" ?>
<robot name="ict_bot">

  <!-- ========== BASE FOOTPRINT (Required by Nav2) ========== -->
  <link name="base_footprint"/>

  <!-- base_link alias so Nav2 nodes that default to "base_link" can find it -->
  <link name="base_link"/>
  <joint name="base_link_joint" type="fixed">
    <origin xyz="0 0 0" rpy="0 0 0"/>
    <parent link="base_footprint"/>
    <child link="base_link"/>
  </joint>

  <joint name="base_footprint_joint" type="fixed">
    <origin xyz="0 0 0" rpy="0 0 1.5708"/>
    <parent link="base_footprint"/>
    <child link="link_base"/>
  </joint>

  <!-- ========== BASE LINK ========== -->
  <link name="link_base">
    <inertial>
      <origin xyz="0 0.00199645 0.0477406" rpy="0 0 0"/>
      <mass value="0.861322"/>
      <inertia ixx="0.00312801" ixy="0" ixz="-0"
               iyy="0.00352738" iyz="3.96227e-05"
               izz="0.00305315"/>
    </inertial>
    <!-- Base body -->
    <visual>
      <origin xyz="-0 0.00157143 0" rpy="0 -0 0"/>
      <geometry>
        <mesh filename="package://ict_bot_nav/urdf/assets/link_base.stl"/>
      </geometry>
      <material name="link_base_material">
        <color rgba="0.615686 0.811765 0.929412 1"/>
      </material>
    </visual>
    <collision>
      <origin xyz="-0 0.00157143 0" rpy="0 -0 0"/>
      <geometry>
        <mesh filename="package://ict_bot_nav/urdf/assets/link_base.stl"/>
      </geometry>
    </collision>
    <!-- Caster wheel (part of base) -->
    <visual>
      <origin xyz="-0 0.0565714 -0.0125" rpy="-0 -1.5708 0"/>
      <geometry>
        <mesh filename="package://ict_bot_nav/urdf/assets/link_caster_wheel.stl"/>
      </geometry>
      <material name="link_caster_wheel_material">
        <color rgba="0.980392 0.713725 0.00392157 1"/>
      </material>
    </visual>
    <collision>
      <origin xyz="-0 0.0565714 -0.0125" rpy="-0 -1.5708 0"/>
      <geometry>
        <mesh filename="package://ict_bot_nav/urdf/assets/link_caster_wheel.stl"/>
      </geometry>
    </collision>
  </link>

  <!-- ========== LEFT WHEEL ========== -->
  <link name="link_left_wheel">
    <inertial>
      <origin xyz="0 0 0.01" rpy="0 0 0"/>
      <mass value="0.172788"/>
      <inertia ixx="0.000113752" ixy="0" ixz="-0"
               iyy="0.000113752" iyz="0"
               izz="0.000215984"/>
    </inertial>
    <visual>
      <origin xyz="0 -0 0.01" rpy="-1.5708 -1.5708 0"/>
      <geometry>
        <mesh filename="package://ict_bot_nav/urdf/assets/link_left_wheel.stl"/>
      </geometry>
      <material name="link_left_wheel_material">
        <color rgba="0.615686 0.811765 0.929412 1"/>
      </material>
    </visual>
    <collision>
      <origin xyz="0 -0 0.01" rpy="-1.5708 -1.5708 0"/>
      <geometry>
        <mesh filename="package://ict_bot_nav/urdf/assets/link_left_wheel.stl"/>
      </geometry>
    </collision>
  </link>

  <joint name="left_wheel_joint" type="continuous">
    <origin xyz="0.08 -0.0284286 0.0275" rpy="-1.5708 -4.5e-11 -1.5708"/>
    <parent link="link_base"/>
    <child link="link_left_wheel"/>
    <axis xyz="0 0 1"/>
    <limit effort="10" velocity="10"/>
  </joint>

  <!-- ========== RIGHT WHEEL ========== -->
  <link name="link_right_wheel">
    <inertial>
      <origin xyz="0 0 -0.01" rpy="0 0 0"/>
      <mass value="0.172788"/>
      <inertia ixx="0.000113752" ixy="0" ixz="-0"
               iyy="0.000113752" iyz="0"
               izz="0.000215984"/>
    </inertial>
    <visual>
      <origin xyz="0 -0 -0.01" rpy="-1.5708 -1.5708 0"/>
      <geometry>
        <mesh filename="package://ict_bot_nav/urdf/assets/link_right_wheel.stl"/>
      </geometry>
      <material name="link_right_wheel_material">
        <color rgba="0.615686 0.811765 0.929412 1"/>
      </material>
    </visual>
    <collision>
      <origin xyz="0 -0 -0.01" rpy="-1.5708 -1.5708 0"/>
      <geometry>
        <mesh filename="package://ict_bot_nav/urdf/assets/link_right_wheel.stl"/>
      </geometry>
    </collision>
  </link>

  <joint name="right_wheel_joint" type="continuous">
    <origin xyz="-0.08 -0.0284286 0.0275" rpy="1.5708 -0 1.5708"/>
    <parent link="link_base"/>
    <child link="link_right_wheel"/>
    <axis xyz="0 0 1"/>
    <limit effort="10" velocity="10"/>
  </joint>

  <!-- ========== LIDAR ========== -->
  <link name="base_scan">
    <inertial>
      <origin xyz="0 0 0" rpy="0 0 0"/>
      <mass value="0.1"/>
      <inertia ixx="1e-05" ixy="0" ixz="0"
               iyy="1e-05" iyz="0"
               izz="1e-05"/>
    </inertial>
    <visual>
      <origin xyz="0 0 0" rpy="0 0 0"/>
      <geometry>
        <cylinder radius="0.03" length="0.02"/>
      </geometry>
      <material name="lidar_material">
        <color rgba="0.1 0.1 0.1 1"/>
      </material>
    </visual>
    <collision>
      <origin xyz="0 0 0" rpy="0 0 0"/>
      <geometry>
        <cylinder radius="0.03" length="0.02"/>
      </geometry>
    </collision>
  </link>

  <joint name="lidar_joint" type="fixed">
    <origin xyz="0 -0.0284286 0.18" rpy="0 0 0"/>
    <parent link="link_base"/>
    <child link="base_scan"/>
  </joint>


  <!-- ========== 3D LIDAR ========== -->
  <link name="lidar_3d">
    <inertial>
      <origin xyz="0 0 0" rpy="0 0 0"/>
      <mass value="0.1"/>
      <inertia ixx="1e-05" ixy="0" ixz="0"
               iyy="1e-05" iyz="0"
               izz="1e-05"/>
    </inertial>
    <visual>
      <origin xyz="0 0 0" rpy="0 0 0"/>
      <geometry>
        <cylinder radius="0.04" length="0.06"/>
      </geometry>
      <material name="lidar3d_material">
        <color rgba="0.2 0.2 0.2 1"/>
      </material>
    </visual>
    <collision>
      <origin xyz="0 0 0" rpy="0 0 0"/>
      <geometry>
        <cylinder radius="0.04" length="0.06"/>
      </geometry>
    </collision>
  </link>

  <joint name="lidar_3d_joint" type="fixed">
    <origin xyz="0 -0.0284286 0.22" rpy="0 0 0"/>
    <parent link="link_base"/>
    <child link="lidar_3d"/>
  </joint>


  <!-- ========== GAZEBO PLUGINS ========== -->

  <!-- Differential Drive Plugin -->
  <gazebo>
    <plugin name="diff_drive" filename="libgazebo_ros_diff_drive.so">
      <ros>
        <remapping>cmd_vel:=cmd_vel</remapping>
        <remapping>odom:=odom</remapping>
      </ros>
      <left_joint>left_wheel_joint</left_joint>
      <right_joint>right_wheel_joint</right_joint>
      <!-- Wheel separation from joint origins: 0.08 - (-0.08) = 0.16 -->
      <wheel_separation>0.16</wheel_separation>
      <!-- Wheel radius calculated from inertia: sqrt(2*izz/mass) = ~0.05 -->
      <wheel_diameter>0.10</wheel_diameter>
      <max_wheel_torque>10</max_wheel_torque>
      <max_wheel_acceleration>1.0</max_wheel_acceleration>
      <publish_odom>true</publish_odom>
      <publish_odom_tf>true</publish_odom_tf>
      <publish_wheel_tf>true</publish_wheel_tf>
      <odometry_frame>odom</odometry_frame>
      <robot_base_frame>base_footprint</robot_base_frame>
    </plugin>
  </gazebo>

  <!-- Caster wheel friction = 0 so it slides freely -->
  <gazebo reference="link_base">
    <mu1>0.0</mu1>
    <mu2>0.0</mu2>
  </gazebo>

  <!-- Wheel friction -->
  <gazebo reference="link_left_wheel">
    <mu1>1.0</mu1>
    <mu2>1.0</mu2>
  </gazebo>
  <gazebo reference="link_right_wheel">
    <mu1>1.0</mu1>
    <mu2>1.0</mu2>
  </gazebo>

  <!-- LiDAR Sensor Plugin -->
  <gazebo reference="base_scan">
    <sensor type="ray" name="lidar_sensor">
      <pose>0 0 0 0 0 0</pose>
      <visualize>true</visualize>
      <update_rate>10</update_rate>
      <ray>
        <scan>
          <horizontal>
            <samples>360</samples>
            <resolution>1</resolution>
            <min_angle>-3.14159</min_angle>
            <max_angle>3.14159</max_angle>
          </horizontal>
        </scan>
        <range>
          <min>0.12</min>
          <max>10.0</max>
          <resolution>0.01</resolution>
        </range>
        <noise>
          <type>gaussian</type>
          <mean>0.0</mean>
          <stddev>0.01</stddev>
        </noise>
      </ray>
      <plugin name="gazebo_ros_lidar" filename="libgazebo_ros_ray_sensor.so">
        <ros>
          <remapping>~/out:=scan</remapping>
        </ros>
        <output_type>sensor_msgs/LaserScan</output_type>
        <frame_name>base_scan</frame_name>
      </plugin>
    </sensor>
  </gazebo>

</robot>
